Workbook

Sheet Dashboard
A1: AI Catalyst HK — Master Tracker Dashboard
A4: Metric | B4: M1 | C4: M2 | D4: M3 | E4: M4 | F4: M5 | G4: M6 | H4: M7 | I4: M8 | J4: M9 | K4: M10 | L4: M11 | M4: M12 | N4: Year Total | O4: Target | P4: Variance
A5: Total Revenue (HKD) | B5: ='Revenue Tracker'!H18 -> 0 | C5: ='Revenue Tracker'!H18 -> 0 | D5: ='Revenue Tracker'!H18 -> 0 | E5: ='Revenue Tracker'!H18 -> 0 | F5: ='Revenue Tracker'!H18 -> 0 | G5: ='Revenue Tracker'!H18 -> 0 | H5: ='Revenue Tracker'!H18 -> 0 | I5: ='Revenue Tracker'!H18 -> 0 | J5: ='Revenue Tracker'!H18 -> 0 | K5: ='Revenue Tracker'!H18 -> 0 | L5: ='Revenue Tracker'!H18 -> 0 | M5: ='Revenue Tracker'!H18 -> 0
A6: Total Costs (HKD) | B6: ='Revenue Tracker'!H33 -> 0 | C6: ='Revenue Tracker'!H33 -> 0 | D6: ='Revenue Tracker'!H33 -> 0 | E6: ='Revenue Tracker'!H33 -> 0 | F6: ='Revenue Tracker'!H33 -> 0 | G6: ='Revenue Tracker'!H33 -> 0 | H6: ='Revenue Tracker'!H33 -> 0 | I6: ='Revenue Tracker'!H33 -> 0 | J6: ='Revenue Tracker'!H33 -> 0 | K6: ='Revenue Tracker'!H33 -> 0 | L6: ='Revenue Tracker'!H33 -> 0 | M6: ='Revenue Tracker'!H33 -> 0
A7: Net Profit/Loss (HKD) | B7: =B5-B6 -> 0 | C7: =C5-C6 -> 0 | D7: =D5-D6 -> 0 | E7: =E5-E6 -> 0 | F7: =F5-F6 -> 0 | G7: =G5-G6 -> 0 | H7: =H5-H6 -> 0 | I7: =I5-I6 -> 0 | ... M7: =M5-M6 -> 0
A8: Affiliate Revenue
A9: Newsletter Revenue
A10: Product Revenue
A11: Sponsored Revenue
A12: Website Visitors
A13: Blog Posts (Cumulative)
A14: Newsletter Free Subs
A15: Newsletter Paid Subs
A16: Total Social Followers

Sheet Revenue Tracker
A1: Category | B1: M1 | C1: M2 | D1: M3 | E1: M4 | F1: M5 | G1: M6 | H1: M7 | I1: M8 | J1: M9 | K1: M10 | L1: M11 | M1: M12
A2: SaaS Affiliate Revenue | B2: 0 | C2: 0 | D2: 2000 | E2: 3000 | F2: 5000 | G2: 10000 | H2: 15000 | I2: 20000 | J2: 25000 | K2: 30000 | L2: 38000 | M2: 45000
A3: Newsletter Revenue | B3: 0 | C3: 0 | D3: 0 | E3: 2000 | F3: 3000 | G3: 5000 | H3: 8000 | I3: 10000 | J3: 15000 | K3: 20000 | L3: 25000 | M3: 30000
A4: Digital Products Revenue | B4: 0 | C4: 0 | D4: 0 | E4: 0 | F4: 1000 | G4: 2000 | H4: 3000 | I4: 5000 | J4: 8000 | K4: 10000 | L4: 12000 | M4: 15000
A5: Sponsored Content Revenue | B5: 0 | C5: 0 | D5: 0 | E5: 0 | F5: 0 | G5: 0 | H5: 0 | I5: 2000 | J5: 5000 | K5: 7000 | L5: 8000 | M5: 10000
A6: TOTAL REVENUE | B6: =SUM(B2:B5) -> 0 | C6: =SUM(C2:C5) -> 0 | D6: =SUM(D2:D5) -> 2000 | E6: =SUM(E2:E5) -> 5000 | F6: =SUM(F2:F5) -> 9000 | G6: =SUM(G2:G5) -> 17000 | H6: =SUM(H2:H5) -> 26000 | I6: =SUM(I2:I5) -> 37000 | ... M6: =SUM(M2:M5) -> 100000
A8: COSTS
A9: Tools & Subscriptions | B9: 1500 | C9: 1500 | D9: 1500 | E9: 1500 | F9: 1500 | G9: 1500 | H9: 1500 | I9: 1500 | J9: 1500 | K9: 1500 | L9: 1500 | M9: 1500
A10: Marketing/Ads | B10: 3000 | C10: 3000 | D10: 5000 | E10: 5000 | F10: 7000 | G10: 7000 | H10: 10000 | I10: 10000 | J10: 10000 | K10: 10000 | L10: 10000 | M10: 10000
A11: Content/Freelance | B11: 0 | C11: 0 | D11: 0 | E11: 0 | F11: 0 | G11: 0 | H11: 5000 | I11: 5000 | J11: 5000 | K11: 8000 | L11: 8000 | M11: 8000
A12: Other | B12: 500 | C12: 500 | D12: 500 | E12: 500 | F12: 500 | G12: 500 | H12: 500 | I12: 500 | J12: 500 | K12: 500 | L12: 500 | M12: 500
A13: TOTAL COSTS | B13: =SUM(B9:B12) -> 5000 | C13: =SUM(C9:C12) -> 5000 | D13: =SUM(D9:D12) -> 7000 | E13: =SUM(E9:E12) -> 7000 | F13: =SUM(F9:F12) -> 9000 | G13: =SUM(G9:G12) -> 9000 | H13: =SUM(H9:H12) -> 17000 | I13: =SUM(I9:I12) -> 17000 | ... M13: =SUM(M9:M12) -> 20000
A14: NET PROFIT/LOSS | B14: =B6-B13 -> -5000 | C14: =C6-C13 -> -5000 | D14: =D6-D13 -> -5000 | E14: =E6-E13 -> -2000 | F14: =F6-F13 -> 0 | G14: =G6-G13 -> 8000 | H14: =H6-H13 -> 9000 | I14: =I6-I13 -> 20000 | ... M14: =M6-M13 -> 80000
A15: Cumulative P/L | B15: =B14 -> -5000 | C15: =B15+C14 -> -10000 | D15: =C15+D14 -> -15000 | E15: =D15+E14 -> -17000 | F15: =E15+F14 -> -17000 | G15: =F15+G14 -> -9000 | H15: =G15+H14 -> 0 | I15: =H15+I14 -> 20000 | J15: =I15+J14 -> 56000 | ... M15: =L15+M14 -> 246000

Sheet Content Tracker
A1: Week# | B1: Date Range | C1: Blog Posts | D1: Blog Target | E1: Newsletter Issues | F1: Newsletter Target | G1: Social Posts Total | H1: Social Target | I1: IG Posts | J1: Threads Posts | K1: FB Posts | L1: LI Posts | M1: WhatsApp Broadcasts | N1: Digital Product Progress | O1: Notes
A2: 1 | B2: 01/01 - 01/07 | D2: 5 | F2: 5 | H2: 100
A3: 2 | B3: 01/08 - 01/14 | D3: 5 | F3: 5 | H3: 100
A4: 3 | B4: 01/15 - 01/21 | D4: 5 | F4: 5 | H4: 100
A5: 4 | B5: 01/22 - 01/28 | D5: 5 | F5: 5 | H5: 100
A6: 5 | B6: 01/29 - 02/04 | D6: 5 | F6: 5 | H6: 100
A7: 6 | B7: 02/05 - 02/11 | D7: 5 | F7: 5 | H7: 100
A8: 7 | B8: 02/12 - 02/18 | D8: 5 | F8: 5 | H8: 100
A9: 8 | B9: 02/19 - 02/25 | D9: 5 | F9: 5 | H9: 100
A10: 9 | B10: 02/26 - 03/04 | D10: 5 | F10: 5 | H10: 100
A11: 10 | B11: 03/05 - 03/11 | D11: 5 | F11: 5 | H11: 100
A12: 11 | B12: 03/12 - 03/18 | D12: 5 | F12: 5 | H12: 100
A13: 12 | B13: 03/19 - 03/25 | D13: 5 | F13: 5 | H13: 100
... A53: 52 | B53: 12/24 - 12/30 | D53: 5 | F53: 5 | H53: 100

Sheet Newsletter Tracker
A1: Issue# | B1: Date | C1: Day | D1: Type | E1: Subject Line | F1: Open Rate% | G1: Click Rate% | H1: New Subs | I1: Unsubscribes | J1: Net Growth | K1: Affiliate Revenue HKD | L1: Ad Revenue HKD | M1: Total Revenue | N1: Cumulative Subs | O1: Notes
A2: 1 | B2: 01/01/2025 | C2: Mon | D2: Free | J2: =H2-I2 -> 0 | M2: =K2+L2 -> 0 | N2: =J2 -> 0
A3: 2 | B3: 01/02/2025 | C3: Tue | D3: Free | J3: =H3-I3 -> 0 | M3: =K3+L3 -> 0 | N3: =N2+J3 -> 0
A4: 3 | B4: 01/03/2025 | C4: Wed | D4: Free | J4: =H4-I4 -> 0 | M4: =K4+L4 -> 0 | N4: =N3+J4 -> 0
A5: 4 | B5: 01/04/2025 | C5: Thu | D5: Free | J5: =H5-I5 -> 0 | M5: =K5+L5 -> 0 | N5: =N4+J5 -> 0
A6: 5 | B6: 01/05/2025 | C6: Fri | D6: Free | J6: =H6-I6 -> 0 | M6: =K6+L6 -> 0 | N6: =N5+J6 -> 0
A7: 6 | B7: 01/08/2025 | C7: Mon | D7: Free | J7: =H7-I7 -> 0 | M7: =K7+L7 -> 0 | N7: =N6+J7 -> 0
A8: 7 | B8: 01/09/2025 | C8: Tue | D8: Free | J8: =H8-I8 -> 0 | M8: =K8+L8 -> 0 | N8: =N7+J8 -> 0
A9: 8 | B9: 01/10/2025 | C9: Wed | D9: Free | J9: =H9-I9 -> 0 | M9: =K9+L9 -> 0 | N9: =N8+J9 -> 0
A10: 9 | B10: 01/11/2025 | C10: Thu | D10: Free | J10: =H10-I10 -> 0 | M10: =K10+L10 -> 0 | N10: =N9+J10 -> 0
A11: 10 | B11: 01/12/2025 | C11: Fri | D11: Free | J11: =H11-I11 -> 0 | M11: =K11+L11 -> 0 | N11: =N10+J11 -> 0
A12: 11 | B12: 01/15/2025 | C12: Mon | D12: Free | J12: =H12-I12 -> 0 | M12: =K12+L12 -> 0 | N12: =N11+J12 -> 0
A13: 12 | B13: 01/16/2025 | C13: Tue | D13: Free | J13: =H13-I13 -> 0 | M13: =K13+L13 -> 0 | N13: =N12+J13 -> 0
A14: 13 | B14: 01/17/2025 | C14: Wed | D14: Free | J14: =H14-I14 -> 0 | M14: =K14+L14 -> 0 | N14: =N13+J14 -> 0
... A261: 260 | B261: 12/28/2025 | C261: Fri | D261: Free | J261: =H261-I261 -> 0 | M261: =K261+L261 -> 0 | N261: =N260+J261 -> 0

Sheet Affiliate Tracker
A1: Tool Name | B1: Category | C1: Commission% | D1: Duration | E1: Cookie Days | F1: Platform | G1: Status | H1: Monthly Revenue HKD | I1: Cumulative Revenue HKD | J1: Priority | K1: Signup URL | L1: Join Date | M1: Last Checked | N1: Notes
A2: Writesonic | B2: AI Writing | C2: 30% | D2: Lifetime | E2: 30 | F2: Web | G2: Active | H2: 0 | I2: 0 | J2: HIGH | L2: 2025-01-15
A3: Notion | B3: Productivity | C3: 50% | D3: Recurring | E3: N/A | F3: Web | G3: Active | H3: 0 | I3: 0 | J3: HIGH | L3: 2025-01-15
A4: ActiveCampaign | B4: Email Marketing | C4: 30% | D4: Recurring | E4: 60 | F4: Web | G4: Active | H4: 0 | I4: 0 | J4: HIGH | L4: 2025-01-15
A5: GetResponse | B5: Email Marketing | C5: 40-60% | D5: Recurring | E5: 180 | F5: Web | G5: Active | H5: 0 | I5: 0 | J5: HIGH | L5: 2025-01-15
A6: HubSpot | B6: CRM | C6: 30% | D6: Recurring | E6: 90 | F6: Web | G6: Active | H6: 0 | I6: 0 | J6: HIGH | L6: 2025-01-15
A7: Copy.ai | B7: AI Writing | C7: 45% | D7: Year 1 | E7: 30 | F7: Web | G7: Active | H7: 0 | I7: 0 | J7: MED | L7: 2025-01-15
A8: Tidio | B8: Chatbot | C8: 30% | D8: Lifetime | E8: 90 | F8: Web | G8: Active | H8: 0 | I8: 0 | J8: MED | L8: 2025-01-15
A9: Thinkific | B9: Learning Platform | C9: 30% | D9: Recurring | E9: 30 | F9: Web | G9: Pending | H9: 0 | I9: 0 | J9: MED
A10: ClickFunnels | B10: Sales Funnel | C10: 30% | D10: Recurring | E10: 30 | F10: Web | G10: Pending | H10: 0 | I10: 0 | J10: MED
A11: Xero | B11: Accounting | C11: 10-25% | D11: Recurring | E11: 90 | F11: Web | G11: Pending | H11: 0 | I11: 0 | J11: MED
A12: LiveChat | B12: Customer Support | C12: 20% | D12: Recurring | E12: 120 | F12: Web | G12: Pending | H12: 0 | I12: 0 | J12: MED
A13: Grammarly | B13: Writing Assistant | C13: $25/sale | D13: Per Sale | E13: 30 | F13: Web | G13: Applied | H13: 0 | I13: 0 | J13: LOW
A14: Canva | B14: Design | C14: ~$36/signup | D14: Per Signup | E14: 30 | F14: Web | G14: Applied | H14: 0 | I14: 0 | J14: LOW
A15: Semrush | B15: SEO Tools | C15: $200/sale | D15: Per Sale | E15: 45 | F15: Web | G15: Applied | H15: 0 | I15: 0 | J15: LOW
A16: Shopify | B16: E-commerce | C16: $100-150 | D16: Per Sale | E16: 30 | F16: Web | G16: Applied | H16: 0 | I16: 0 | J16: MED
A17: NordVPN | B17: VPN | C17: 40% | D17: Recurring | E17: 30 | F17: Web | G17: Active | H17: 0 | I17: 0 | J17: LOW | L17: 2025-01-15
A18: Surfshark | B18: VPN | C18: 40% | D18: Recurring | E18: 30 | F18: Web | G18: Active | H18: 0 | I18: 0 | J18: LOW | L18: 2025-01-15
A19: ExpressVPN | B19: VPN | C19: $13/sale | D19: Per Sale | E19: 30 | F19: Web | G19: Active | H19: 0 | I19: 0 | J19: LOW | L19: 2025-01-15
A20: TOTAL REVENUE | H20: =SUM(H2:H19) -> 0 | I20: =SUM(I2:I19) -> 0

Sheet Subscriber Pipeline
A1: Name | B1: Email | C1: Source | D1: Status | E1: Subscribe Date | F1: Industry | G1: Lifetime Value HKD | H1: Conversion Date | I1: Notes

Sheet KPI Dashboard
A1: KPI Category | B1: Metric | C1: M1 | D1: M2 | E1: M3 | F1: M4 | G1: M5 | H1: M6 | I1: M7 | J1: M8 | K1: M9 | L1: M10 | M1: M11 | N1: M12
A2: Revenue KPIs | B2: Total Revenue | C2: ='Revenue Tracker'!C6 -> 0 | D2: ='Revenue Tracker'!D6 -> 2000 | E2: ='Revenue Tracker'!E6 -> 5000 | F2: ='Revenue Tracker'!F6 -> 9000 | G2: ='Revenue Tracker'!G6 -> 17000 | H2: ='Revenue Tracker'!H6 -> 26000 | I2: ='Revenue Tracker'!I6 -> 37000 | J2: ='Revenue Tracker'!J6 -> 53000 | ... N2: ='Revenue Tracker'!N6 -> 0
B3: Affiliate Revenue
B4: Newsletter Revenue
B5: Product Revenue
B6: Sponsored Revenue
B7: MoM Growth %
A8: Cost KPIs | B8: Total Costs
B9: Marketing Spend
B10: Tool Costs
A11: Traffic KPIs | B11: Website Visitors
B12: Organic Traffic %
B13: Paid Traffic %
B14: Top Landing Page
A15: Content KPIs | B15: Blog Posts (Cumulative)
B16: Posts This Month
B17: Avg Word Count
B18: Top Keyword Position
A19: Newsletter KPIs | B19: Free Subscribers
B20: Paid Subscribers
B21: Conversion Rate % | C21: =IF(C19+C20=0,0,C20/(C19+C20)*100) -> 0 | D21: =IF(D19+D20=0,0,D20/(D19+D20)*100) -> 0 | E21: =IF(E19+E20=0,0,E20/(E19+E20)*100) -> 0 | F21: =IF(F19+F20=0,0,F20/(F19+F20)*100) -> 0 | G21: =IF(G19+G20=0,0,G20/(G19+G20)*100) -> 0 | H21: =IF(H19+H20=0,0,H20/(H19+H20)*100) -> 0 | I21: =IF(I19+I20=0,0,I20/(I19+I20)*100) -> 0 | J21: =IF(J19+J20=0,0,J20/(J19+J20)*100) -> 0 | ... N21: =IF(N19+N20=0,0,N20/(N19+N20)*100) -> 0
B22: Open Rate %
B23: Click Rate %
B24: Churn Rate %
A25: Social KPIs | B25: Total Followers
B26: IG Followers
B27: Threads Followers
B28: FB Followers
B29: LI Followers
B30: Daily Posts Avg
B31: Engagement Rate %
A32: Product KPIs | B32: Products Listed
B33: Monthly Product Revenue
B34: Avg Product Price

Sheet Weekly Reviews
A1: Week# | B1: Date Range | C1: Total Revenue HKD | D1: Affiliate Rev | E1: Newsletter Rev | F1: Product Rev | G1: Sponsor Rev | H1: Newsletter Free Subs | I1: Newsletter Paid Subs | J1: Blog Posts Published | K1: Website Visitors | L1: Social Followers Total | M1: Key Learning | N1: Next Week Priority
A2: 1 | B2: 01/01 - 01/07 | C2: 0
A3: 2 | B3: 01/08 - 01/14 | C3: 0
A4: 3 | B4: 01/15 - 01/21 | C4: 0
A5: 4 | B5: 01/22 - 01/28 | C5: 0
A6: 5 | B6: 01/29 - 02/04 | C6: 0
A7: 6 | B7: 02/05 - 02/11 | C7: 0
A8: 7 | B8: 02/12 - 02/18 | C8: 0
A9: 8 | B9: 02/19 - 02/25 | C9: 0
A10: 9 | B10: 02/26 - 03/04 | C10: 0
A11: 10 | B11: 03/05 - 03/11 | C11: 0
A12: 11 | B12: 03/12 - 03/18 | C12: 0
A13: 12 | B13: 03/19 - 03/25 | C13: 0
... A53: 52 | B53: 12/24 - 12/30 | C53: 0

Sheet Digital Products
A1: Product Name | B1: Type | C1: Price HKD | D1: Platform | E1: Status | F1: Launch Date | G1: Sales Count | H1: Monthly Revenue HKD | I1: Cumulative Revenue | J1: Customer Rating | K1: Notes
A22: TOTAL REVENUE | H22: =SUM(H2:H21) -> 0 | I22: =SUM(I2:I21) -> 0

Sheet Budget Tracker
A1: Category | B1: Subcategory | C1: M1 | D1: M2 | E1: M3 | F1: M4 | G1: M5 | H1: M6 | I1: M7 | J1: M8 | K1: M9 | L1: M10 | M1: M11 | N1: M12 | O1: Total
A2: Tool Subscriptions | B2: Claude | O2: =SUM(C2:N2) -> 0
B3: Notion | O3: =SUM(C3:N3) -> 0
B4: 10Web | O4: =SUM(C4:N4) -> 0
B5: Beehiiv | O5: =SUM(C5:N5) -> 0
B6: Feedly | O6: =SUM(C6:N6) -> 0
B7: Canva | O7: =SUM(C7:N7) -> 0
B8: Cloudflare | O8: =SUM(C8:N8) -> 0
B9: n8n VPS | O9: =SUM(C9:N9) -> 0
B10: RankMath | O10: =SUM(C10:N10) -> 0
B11: WPML | O11: =SUM(C11:N11) -> 0
A12: Tool Subscriptions Subtotal | C12: =SUM(C2:C11) -> 0 | D12: =SUM(D2:D11) -> 0 | E12: =SUM(E2:E11) -> 0 | F12: =SUM(F2:F11) -> 0 | G12: =SUM(G2:G11) -> 0 | H12: =SUM(H2:H11) -> 0 | I12: =SUM(I2:I11) -> 0 | J12: =SUM(J2:J11) -> 0 | ... O12: =SUM(O2:O11) -> 0
A13: Marketing | B13: FB/IG Ads | O13: =SUM(C13:N13) -> 0
B14: Google Ads | O14: =SUM(C14:N14) -> 0
B15: Newsletter Boosts | O15: =SUM(C15:N15) -> 0
A16: Marketing Subtotal | C16: =SUM(C13:C15) -> 0 | D16: =SUM(D13:D15) -> 0 | E16: =SUM(E13:E15) -> 0 | F16: =SUM(F13:F15) -> 0 | G16: =SUM(G13:G15) -> 0 | H16: =SUM(H13:H15) -> 0 | I16: =SUM(I13:I15) -> 0 | J16: =SUM(J13:J15) -> 0 | ... O16: =SUM(O13:O15) -> 0
A17: Content | B17: Freelancers | O17: =SUM(C17:N17) -> 0
B18: Design | O18: =SUM(C18:N18) -> 0
A19: Content Subtotal | C19: =SUM(C17:C18) -> 0 | D19: =SUM(D17:D18) -> 0 | E19: =SUM(E17:E18) -> 0 | F19: =SUM(F17:F18) -> 0 | G19: =SUM(G17:G18) -> 0 | H19: =SUM(H17:H18) -> 0 | I19: =SUM(I17:I18) -> 0 | J19: =SUM(J17:J18) -> 0 | ... O19: =SUM(O17:O18) -> 0
A20: Operations | B20: Domain | O20: =SUM(C20:N20) -> 0
B21: Misc | O21: =SUM(C21:N21) -> 0
A22: Operations Subtotal | C22: =SUM(C20:C21) -> 0 | D22: =SUM(D20:D21) -> 0 | E22: =SUM(E20:E21) -> 0 | F22: =SUM(F20:F21) -> 0 | G22: =SUM(G20:G21) -> 0 | H22: =SUM(H20:H21) -> 0 | I22: =SUM(I20:I21) -> 0 | J22: =SUM(J20:J21) -> 0 | ... O22: =SUM(O20:O21) -> 0
A23: GRAND TOTAL | C23: =SUM(C2:C22) -> 0 | D23: =SUM(D2:D22) -> 0 | E23: =SUM(E2:E22) -> 0 | F23: =SUM(F2:F22) -> 0 | G23: =SUM(G2:G22) -> 0 | H23: =SUM(H2:H22) -> 0 | I23: =SUM(I2:I22) -> 0 | J23: =SUM(J2:J22) -> 0 | ... O23: =SUM(O2:O22) -> 0

Sheet 90-Day Checklist
A1: Phase | B1: Week | C1: Task | D1: Status | E1: Due Date | F1: Completed Date | G1: Owner | H1: Notes
A2: Phase 1: Foundation | B2: W1 | C2: Finalize newsletter branding & design | D2: Not Started | E2: 2025-01-08 | G2: Owner
B3: W1 | C3: Set up email infrastructure (Beehiiv) | D3: Not Started | E3: 2025-01-08 | G3: Owner
B4: W1 | C4: Create subscriber onboarding sequence | D4: Not Started | E4: 2025-01-15 | G4: Owner
B5: W1 | C5: Set up analytics dashboard (GA4, email) | D5: Not Started | E5: 2025-01-15 | G5: Owner
B6: W2 | C6: Launch first 5 newsletters (Jan 13-17) | D6: Not Started | E6: 2025-01-17 | G6: Owner
B7: W2 | C7: Create blog posting workflow | D7: Not Started | E7: 2025-01-17 | G7: Owner
B8: W2 | C8: Finalize SEO strategy & keyword map | D8: Not Started | E8: 2025-01-22 | G8: Owner
B9: W3 | C9: Publish first 5 blog posts | D9: Not Started | E9: 2025-01-31 | G9: Owner
B10: W3 | C10: Set up social media posting cadence | D10: Not Started | E10: 2025-01-31 | G10: Owner
B11: W3 | C11: Create Instagram content calendar | D11: Not Started | E11: 2025-01-31 | G11: Owner
B12: W4 | C12: Launch Facebook community group | D12: Not Started | E12: 2025-02-07 | G12: Owner
B13: W4 | C13: Set up LinkedIn publishing workflow | D13: Not Started | E13: 2025-02-07 | G13: Owner
B14: W4 | C14: Join Threads & build initial presence | D14: Not Started | E14: 2025-02-07 | G14: Owner
A15: Phase 1: Foundation | B15: W5 | C15: Create first digital product (Prompt Pack) | D15: Not Started | E15: 2025-02-21 | G15: Owner
B16: W5 | C16: Set up product landing page | D16: Not Started | E16: 2025-02-21 | G16: Owner
B17: W5 | C17: Apply for first 5 affiliate programs | D17: Not Started | E17: 2025-02-21 | G17: Owner
B18: W6 | C18: Publish 5 blog posts on SEO topics | D18: Not Started | E18: 2025-02-28 | G18: Owner
B19: W6 | C19: Reach 500 newsletter subscribers | D19: Not Started | E19: 2025-02-28 | G19: Owner
B20: W6 | C20: Get first 10 affiliate link clicks | D20: Not Started | E20: 2025-02-28 | G20: Owner
B21: W7 | C21: Create viral content ideas document | D21: Not Started | E21: 2025-03-07 | G21: Owner
B22: W7 | C22: Launch WhatsApp newsletter channel | D22: Not Started | E22: 2025-03-07 | G22: Owner
B23: W8 | C23: Reach 1000 newsletter subscribers | D23: Not Started | E23: 2025-03-21 | G23: Owner
B24: W8 | C24: Generate first affiliate revenue (HKD) | D24: Not Started | E24: 2025-03-21 | G24: Owner
B25: W8 | C25: Create sponsor media kit | D25: Not Started | E25: 2025-03-21 | G25: Owner
B26: W9 | C26: Publish first 5 Threads posts weekly | D26: Not Started | E26: 2025-03-28 | G26: Owner
B27: W9 | C27: Reach 10K total social followers | D27: Not Started | E27: 2025-03-28 | G27: Owner
... B30: W12 | C30: Phase 1 Review & Optimization | D30: Not Started | E30: 2025-04-25 | G30: Owner
A31: Phase 2: Content Engine | B31: W13 | C31: Scale content production (10+ posts/week) | D31: Not Started | E31: 2025-05-09 | G31: Owner
B32: W13 | C32: Optimize blog for conversions (CTAs) | D32: Not Started | E32: 2025-05-09 | G32: Owner
B33: W14 | C33: Reach 2000 newsletter subscribers | D33: Not Started | E33: 2025-05-16 | G33: Owner
B34: W14 | C34: Launch 3rd digital product (Template) | D34: Not Started | E34: 2025-05-16 | G34: Owner
B35: W15 | C35: Set up email segmentation | D35: Not Started | E35: 2025-05-30 | G35: Owner
B36: W15 | C36: Create 5 long-form guides (3000+ words) | D36: Not Started | E36: 2025-05-30 | G36: Owner
B37: W16 | C37: Launch paid newsletter tier | D37: Not Started | E37: 2025-06-13 | G37: Owner
B38: W16 | C38: Get 10 paid subscribers minimum | D38: Not Started | E38: 2025-06-13 | G38: Owner
B39: W18 | C39: Reach 5000 newsletter subscribers (free+paid) | D39: Not Started | E39: 2025-06-27 | G39: Owner
B40: W18 | C40: Generate HKD 5000 monthly revenue | D40: Not Started | E40: 2025-06-27 | G40: Owner
B41: W20 | C41: Build affiliate network (20+ programs) | D41: Not Started | E41: 2025-07-25 | G41: Owner
B42: W20 | C42: Create affiliate tracking system | D42: Not Started | E42: 2025-07-25 | G42: Owner
...
